<?xml version="1.0"?>
<robot xmlns:xacro="http://ros.org/wiki/xacro">

  <xacro:include filename="$(find onrobot_description)/urdf/inc/common_utils.xacro" />
  <xacro:include filename="$(find onrobot_description)/urdf/inc/2fg7_materials.xacro" />

  <xacro:macro name="onrobot_2fg7" params="prefix onrobot_type:='2fg7'">
    
    <!-- Base Link -->
    <link name="${prefix}onrobot_base_link">
      <inertial>
        <origin xyz="0 0 0" rpy="0 0 0"/>
        <mass value="0.3"/>
        <inertia ixx="0.0005" ixy="0.0" ixz="0.0" iyy="0.0005" iyz="0.0" izz="0.0005"/>
      </inertial>
      <visual>
        <origin xyz="0 0 0" rpy="0 0 0"/>
        <geometry>
          <mesh filename="package://onrobot_description/meshes/2fg7/visual/base_link.stl" scale="0.001 0.001 0.001"/>
        </geometry>
        <material name="onrobot_silver"/>
      </visual>
      <collision>
        <origin xyz="0 0 0" rpy="0 0 0"/>
        <geometry>
          <box size="0.045 0.045 0.04"/>
        </geometry>
      </collision>
    </link>

    <!-- Finger Links -->
    <link name="${prefix}left_finger_link">
      <inertial>
        <origin xyz="0 0 0" rpy="0 0 0"/>
        <mass value="0.05"/>
        <inertia ixx="0.00005" ixy="0.0" ixz="0.0" iyy="0.00005" iyz="0.0" izz="0.00005"/>
      </inertial>
      <visual>
        <origin xyz="0 0 0" rpy="0 0 0"/>
        <geometry>
          <mesh filename="package://onrobot_description/meshes/2fg7/visual/left_finger_link.stl" scale="0.001 0.001 0.001"/>
        </geometry>
        <material name="onrobot_silver"/>
      </visual>
      <collision>
        <origin xyz="0 0 0" rpy="0 0 0"/>
        <geometry>
          <box size="0.008 0.025 0.06"/>
        </geometry>
      </collision>
    </link>

    <link name="${prefix}right_finger_link">
      <inertial>
        <origin xyz="0 0 0" rpy="0 0 0"/>
        <mass value="0.05"/>
        <inertia ixx="0.00005" ixy="0.0" ixz="0.0" iyy="0.00005" iyz="0.0" izz="0.00005"/>
      </inertial>
      <visual>
        <origin xyz="0 0 0" rpy="0 0 0"/>
        <geometry>
          <mesh filename="package://onrobot_description/meshes/2fg7/visual/right_finger_link.stl" scale="0.001 0.001 0.001"/>
        </geometry>
        <material name="onrobot_silver"/>
      </visual>
      <collision>
        <origin xyz="0 0 0" rpy="0 0 0"/>
        <geometry>
          <box size="0.008 0.025 0.06"/>
        </geometry>
      </collision>
    </link>

    <!-- Dummy link for the main control joint -->
    <link name="${prefix}finger_width_mock_link"/>
    
    <!-- Main control joint (finger_width) -->
    <joint name="${prefix}finger_width" type="prismatic">
      <origin xyz="0 0 0" rpy="0 0 0"/>
      <parent link="${prefix}onrobot_base_link"/>
      <child link="${prefix}finger_width_mock_link"/>
      <axis xyz="0 0 1"/>
      <limit lower="0" upper="0.035" velocity="0.45" effort="140"/>
    </joint>

    <!-- Left Finger Joint -->
    <joint name="${prefix}left_finger_joint" type="prismatic">
      <origin xyz="-0.0175 0 0" rpy="0 0 0"/>
      <parent link="${prefix}onrobot_base_link"/>
      <child link="${prefix}left_finger_link"/>
      <axis xyz="1 0 0"/>
      <limit lower="0.0" upper="0.0175" effort="140" velocity="0.45"/>
      <mimic joint="${prefix}finger_width" multiplier="0.5" offset="0"/>
    </joint>

    <!-- Right Finger Joint -->
    <joint name="${prefix}right_finger_joint" type="prismatic">
      <origin xyz="0.0175 0 0" rpy="0 0 0"/>
      <parent link="${prefix}onrobot_base_link"/>
      <child link="${prefix}right_finger_link"/>
      <axis xyz="-1 0 0"/>
      <limit lower="-0.0175" upper="0.0" effort="140" velocity="0.45"/>
      <mimic joint="${prefix}finger_width" multiplier="0.5" offset="0"/>
    </joint>

    <!-- TCP Link -->
    <link name="${prefix}gripper_tcp"/>
    <joint name="${prefix}tcp_joint" type="fixed">
      <origin xyz="0 0 0.08" rpy="0 0 0"/>
      <parent link="${prefix}onrobot_base_link"/>
      <child link="${prefix}gripper_tcp"/>
    </joint>

    <!-- Transmission for ROS Control -->
    <xacro:transmission_macro prefix="${prefix}" joint_name="finger_width"/>

  </xacro:macro>
</robot>