<?xml version="1.0"?>
<robot xmlns:xacro="http://ros.org/wiki/xacro">
  <xacro:include filename="$(find onrobot_description)/urdf/inc/common_utils.xacro" />
  <xacro:include filename="$(find onrobot_description)/urdf/inc/2fg7_materials.xacro" />

  <!-- Macro for OnRobot 3FG15 with rotation around RZ only -->
  <xacro:macro name="onrobot_3fg15_rotatable" params="prefix">
    <!-- Constants -->
    <xacro:property name="finger_radius" value="0.05875" />

    <!-- Base Link (fixed to robot) -->
    <link name="${prefix}onrobot_base_link">
      <inertial>
        <origin xyz="0 0 0" rpy="0 0 0"/>
        <mass value="1.2"/>
        <inertia ixx="0.012" ixy="0.0" ixz="0.0" iyy="0.012" iyz="0.0" izz="0.008"/>
      </inertial>
      <visual>
        <origin xyz="0 0 0" rpy="0 0 0"/>
        <geometry>
          <mesh filename="package://onrobot_description/meshes/3fg15/visual/base.stl" scale="0.001 0.001 0.001"/>
        </geometry>
        <material name="onrobot_silver"/>
      </visual>
      <collision>
        <origin xyz="0 0 0" rpy="0 0 0"/>
        <geometry>
          <mesh filename="package://onrobot_description/meshes/3fg15/collision/base.stl" scale="0.001 0.001 0.001"/>
        </geometry>
      </collision>
    </link>

    <!-- Rotating frame: all fingers rotate together around Z -->
    <link name="${prefix}rotating_frame"/>
    <joint name="${prefix}gripper_rotation" type="revolute">
      <parent link="${prefix}onrobot_base_link"/>
      <child link="${prefix}rotating_frame"/>
      <origin xyz="0 0 0" rpy="0 0 0"/>
      <axis xyz="0 0 1"/>
      <limit lower="-3.1416" upper="3.1416" effort="200" velocity="1.0"/>
    </joint>

    <!-- Left Finger (fixed pose, rotates with frame) -->
    <link name="${prefix}left_finger_link">
      <inertial>
        <origin xyz="0 0 0" rpy="0 0 0"/>
        <mass value="0.08"/>
        <inertia ixx="0.00008" ixy="0.0" ixz="0.0" iyy="0.00008" iyz="0.0" izz="0.00008"/>
      </inertial>
      <visual>
        <origin xyz="0 0 0" rpy="0 0 0"/>
        <geometry>
          <mesh filename="package://onrobot_description/meshes/3fg15/visual/left_finger.stl" scale="0.001 0.001 0.001"/>
        </geometry>
        <material name="onrobot_silver"/>
      </visual>
      <collision>
        <origin xyz="0 0 0" rpy="0 0 0"/>
        <geometry>
          <mesh filename="package://onrobot_description/meshes/3fg15/collision/left_finger.stl" scale="0.001 0.001 0.001"/>
        </geometry>
      </collision>
    </link>
    <joint name="${prefix}left_finger_fixed" type="fixed">
      <parent link="${prefix}rotating_frame"/>
      <child link="${prefix}left_finger_link"/>
      <origin xyz="0 0 0" rpy="0 0 0"/>
    </joint>

    <!-- Right Finger -->
    <link name="${prefix}right_finger_link">
      <inertial>
        <origin xyz="0 0 0" rpy="0 0 0"/>
        <mass value="0.08"/>
        <inertia ixx="0.00008" ixy="0.0" ixz="0.0" iyy="0.00008" iyz="0.0" izz="0.00008"/>
      </inertial>
      <visual>
        <origin xyz="0 0 0" rpy="0 0 0"/>
        <geometry>
          <mesh filename="package://onrobot_description/meshes/3fg15/visual/right_finger.stl" scale="0.001 0.001 0.001"/>
        </geometry>
        <material name="onrobot_silver"/>
      </visual>
      <collision>
        <origin xyz="0 0 0" rpy="0 0 0"/>
        <geometry>
          <mesh filename="package://onrobot_description/meshes/3fg15/collision/right_finger.stl" scale="0.001 0.001 0.001"/>
        </geometry>
      </collision>
    </link>
    <joint name="${prefix}right_finger_fixed" type="fixed">
      <parent link="${prefix}rotating_frame"/>
      <child link="${prefix}right_finger_link"/>
      <origin xyz="0 0 0" rpy="0 0 0"/>
    </joint>

    <!-- Middle Finger -->
    <link name="${prefix}middle_finger_link">
      <inertial>
        <origin xyz="0 0 0" rpy="0 0 0"/>
        <mass value="0.08"/>
        <inertia ixx="0.00008" ixy="0.0" ixz="0.0" iyy="0.00008" iyz="0.0" izz="0.00008"/>
      </inertial>
      <visual>
        <origin xyz="0 0 0" rpy="0 0 0"/>
        <geometry>
          <mesh filename="package://onrobot_description/meshes/3fg15/visual/middle_finger.stl" scale="0.001 0.001 0.001"/>
        </geometry>
        <material name="onrobot_silver"/>
      </visual>
      <collision>
        <origin xyz="0 0 0" rpy="0 0 0"/>
        <geometry>
          <mesh filename="package://onrobot_description/meshes/3fg15/collision/middle_finger.stl" scale="0.001 0.001 0.001"/>
        </geometry>
      </collision>
    </link>
    <joint name="${prefix}middle_finger_fixed" type="fixed">
      <parent link="${prefix}rotating_frame"/>
      <child link="${prefix}middle_finger_link"/>
      <origin xyz="0 0 0" rpy="0 0 0"/>
    </joint>

    <!-- TCP Link (opcional, fijo al rotating_frame) -->
    <link name="${prefix}gripper_tcp"/>
    <joint name="${prefix}tcp_joint" type="fixed">
      <parent link="${prefix}rotating_frame"/>
      <child link="${prefix}gripper_tcp"/>
      <origin xyz="0 0 0.08" rpy="0 0 0"/>
    </joint>

    <!-- Transmission for rotation control -->
    <xacro:transmission_macro prefix="${prefix}" joint_name="gripper_rotation"/>
  </xacro:macro>
</robot>