<?xml version="1.0"?>
<robot xmlns:xacro="http://ros.org/wiki/xacro">
  <xacro:include filename="$(find onrobot_description)/urdf/inc/common_utils.xacro" />
  <xacro:include filename="$(find onrobot_description)/urdf/inc/2fg7_materials.xacro" />

  <!-- Macro for OnRobot 3FG15 three-finger revolutionary gripper -->
  <xacro:macro name="onrobot_3fg15" params="prefix onrobot_type:='3fg15'">

    <!-- Constants for 3FG15 -->
    <xacro:property name="max_aperture" value="0.1175" /> <!-- 117.5mm in meters -->
    <xacro:property name="min_aperture" value="0.0088" /> <!-- 8.8mm in meters -->
    <xacro:property name="finger_radius" value="0.05875" /> <!-- Radius from center to finger tip -->

    <!-- Base Link -->
    <link name="${prefix}onrobot_base_link">
      <inertial>
        <origin xyz="0 0 0" rpy="0 0 0"/>
        <mass value="1.2"/>
        <inertia ixx="0.012" ixy="0.0" ixz="0.0" iyy="0.012" iyz="0.0" izz="0.008"/>
      </inertial>
      <visual>
        <origin xyz="0 0 0" rpy="0 0 0"/>
        <geometry>
          <mesh filename="package://onrobot_description/meshes/3fg15/visual/base.stl" scale="0.001 0.001 0.001"/>
        </geometry>
        <material name="onrobot_silver"/>
      </visual>
      <collision>
        <origin xyz="0 0 0" rpy="0 0 0"/>
        <geometry>
          <mesh filename="package://onrobot_description/meshes/3fg15/collision/base.stl" scale="0.001 0.001 0.001"/>
        </geometry>
      </collision>
    </link>

    <!-- Left Finger Link -->
    <link name="${prefix}left_finger_link">
      <inertial>
        <origin xyz="0 0 0" rpy="0 0 0"/>
        <mass value="0.08"/>
        <inertia ixx="0.00008" ixy="0.0" ixz="0.0" iyy="0.00008" iyz="0.0" izz="0.00008"/>
      </inertial>
      <visual>
        <origin xyz="0 0 0" rpy="0 0 0"/>
        <geometry>
          <mesh filename="package://onrobot_description/meshes/3fg15/visual/left_finger.stl" scale="0.001 0.001 0.001"/>
        </geometry>
        <material name="onrobot_silver"/>
      </visual>
      <collision>
        <origin xyz="0 0 0" rpy="0 0 0"/>
        <geometry>
          <mesh filename="package://onrobot_description/meshes/3fg15/collision/left_finger.stl" scale="0.001 0.001 0.001"/>
        </geometry>
      </collision>
    </link>

    <!-- Right Finger Link -->
    <link name="${prefix}right_finger_link">
      <inertial>
        <origin xyz="0 0 0" rpy="0 0 0"/>
        <mass value="0.08"/>
        <inertia ixx="0.00008" ixy="0.0" ixz="0.0" iyy="0.00008" iyz="0.0" izz="0.00008"/>
      </inertial>
      <visual>
        <origin xyz="0 0 0" rpy="0 0 0"/>
        <geometry>
          <mesh filename="package://onrobot_description/meshes/3fg15/visual/right_finger.stl" scale="0.001 0.001 0.001"/>
        </geometry>
        <material name="onrobot_silver"/>
      </visual>
      <collision>
        <origin xyz="0 0 0" rpy="0 0 0"/>
        <geometry>
          <mesh filename="package://onrobot_description/meshes/3fg15/collision/right_finger.stl" scale="0.001 0.001 0.001"/>
        </geometry>
      </collision>
    </link>

    <!-- Middle Finger Link -->
    <link name="${prefix}middle_finger_link">
      <inertial>
        <origin xyz="0 0 0" rpy="0 0 0"/>
        <mass value="0.08"/>
        <inertia ixx="0.00008" ixy="0.0" ixz="0.0" iyy="0.00008" iyz="0.0" izz="0.00008"/>
      </inertial>
      <visual>
        <origin xyz="0 0 0" rpy="0 0 0"/>
        <geometry>
          <mesh filename="package://onrobot_description/meshes/3fg15/visual/middle_finger.stl" scale="0.001 0.001 0.001"/>
        </geometry>
        <material name="onrobot_silver"/>
      </visual>
      <collision>
        <origin xyz="0 0 0" rpy="0 0 0"/>
        <geometry>
          <mesh filename="package://onrobot_description/meshes/3fg15/collision/middle_finger.stl" scale="0.001 0.001 0.001"/>
        </geometry>
      </collision>
    </link>

    <!-- Dummy link for the main control joint -->
    <link name="${prefix}finger_width_mock_link"/>
    
    <!-- Main control joint (finger_width) - represents aperture diameter -->
    <joint name="${prefix}finger_width" type="prismatic">
      <origin xyz="0 0 0" rpy="0 0 0"/>
      <parent link="${prefix}onrobot_base_link"/>
      <child link="${prefix}finger_width_mock_link"/>
      <axis xyz="0 0 1"/>
      <limit lower="${min_aperture}" upper="${max_aperture}" velocity="0.25" effort="200"/>
    </joint>

    <!-- Left Finger Joint (Revolute) -->
    <joint name="${prefix}left_finger_joint" type="revolute">
      <origin xyz="0 0 0" rpy="0 0 0"/>
      <parent link="${prefix}onrobot_base_link"/>
      <child link="${prefix}left_finger_link"/>
      <axis xyz="0 0 1"/>
      <limit lower="${-pi/3}" upper="${pi/3}" effort="200" velocity="0.25"/>
      <mimic joint="${prefix}finger_width" multiplier="${(2*pi/3)/(max_aperture - min_aperture)}" offset="${-pi/3 - (2*pi/3)/(max_aperture - min_aperture) * min_aperture}"/>
    </joint>

    <!-- Right Finger Joint (Revolute) -->
    <joint name="${prefix}right_finger_joint" type="revolute">
      <origin xyz="0 0 0" rpy="0 0 0"/>
      <parent link="${prefix}onrobot_base_link"/>
      <child link="${prefix}right_finger_link"/>
      <axis xyz="0 0 1"/>
      <limit lower="${-pi/3}" upper="${pi/3}" effort="200" velocity="0.25"/>
      <mimic joint="${prefix}finger_width" multiplier="${(2*pi/3)/(max_aperture - min_aperture)}" offset="${-pi/3 - (2*pi/3)/(max_aperture - min_aperture) * min_aperture}"/>
    </joint>

    <!-- Middle Finger Joint (Revolute) -->
    <joint name="${prefix}middle_finger_joint" type="revolute">
      <origin xyz="0 0 0" rpy="0 0 0"/>
      <parent link="${prefix}onrobot_base_link"/>
      <child link="${prefix}middle_finger_link"/>
      <axis xyz="0 0 1"/>
      <limit lower="${-pi/3}" upper="${pi/3}" effort="200" velocity="0.25"/>
      <mimic joint="${prefix}finger_width" multiplier="${(2*pi/3)/(max_aperture - min_aperture)}" offset="${-pi/3 - (2*pi/3)/(max_aperture - min_aperture) * min_aperture}"/>
    </joint>

    <!-- TCP Link -->
    <link name="${prefix}gripper_tcp"/>
    <joint name="${prefix}tcp_joint" type="fixed">
      <origin xyz="0 0 0.08" rpy="0 0 0"/>
      <parent link="${prefix}onrobot_base_link"/>
      <child link="${prefix}gripper_tcp"/>
    </joint>

    <!-- Transmission for ROS Control -->
    <xacro:transmission_macro prefix="${prefix}" joint_name="finger_width"/>

  </xacro:macro>
</robot>