<?xml version="1.0"?>
<robot xmlns:xacro="http://ros.org/wiki/xacro">

  <xacro:include filename="$(find onrobot_description)/urdf/inc/common_utils.xacro" />

  <!-- Macro para OnRobot 3FG15 -->
  <xacro:macro name="onrobot_3fg15" params="prefix onrobot_type:='3fg15'">

    <!-- Constantes -->
    <xacro:property name="min_diameter" value="0.000" />
    <xacro:property name="max_diameter" value="0.150" />

    <!-- Base Link -->
    <link name="${prefix}onrobot_base_link">
      <inertial>
        <origin xyz="0 0 0.04" rpy="0 0 0"/>
        <mass value="1.2"/>
        <inertia ixx="0.012" ixy="0.0" ixz="0.0" iyy="0.012" iyz="0.0" izz="0.008"/>
      </inertial>
      <visual>
        <origin xyz="0 0 0" rpy="0 0 0"/>
        <geometry>
          <mesh filename="package://onrobot_description/meshes/3fg15/visual/base.stl" scale="0.001 0.001 0.001"/>
        </geometry>
      </visual>
      <collision>
        <origin xyz="0 0 0.04" rpy="0 0 0"/>
        <geometry>
          <mesh filename="package://onrobot_description/meshes/3fg15/collision/base.stl" scale="0.001 0.001 0.001"/>
        </geometry>
      </collision>
    </link>

    <!-- === DEDOS (con movimiento real via mimic) === -->

    <!-- Left Finger -->
    <link name="${prefix}left_finger_link">
      <inertial>
        <origin xyz="0 0 0" rpy="0 0 0"/>
        <mass value="0.08"/>
        <inertia ixx="0.00008" ixy="0.0" ixz="0.0" iyy="0.00008" iyz="0.0" izz="0.00008"/>
      </inertial>
      <visual>
        <origin xyz="0 0 0" rpy="0 0 0"/>
        <geometry>
          <mesh filename="package://onrobot_description/meshes/3fg15/visual/left_finger.stl" scale="0.001 0.001 0.001"/>
        </geometry>
      </visual>
      <collision>
        <origin xyz="0 0 0" rpy="0 0 0"/>
        <geometry>
          <mesh filename="package://onrobot_description/meshes/3fg15/collision/left_finger.stl" scale="0.001 0.001 0.001"/>
        </geometry>
      </collision>
    </link>

    <!-- Right Finger -->
    <link name="${prefix}right_finger_link">
      <inertial>
        <origin xyz="0 0 0" rpy="0 0 0"/>
        <mass value="0.08"/>
        <inertia ixx="0.00008" ixy="0.0" ixz="0.0" iyy="0.00008" iyz="0.0" izz="0.00008"/>
      </inertial>
      <visual>
        <origin xyz="0 0 0" rpy="0 0 0"/>
        <geometry>
          <mesh filename="package://onrobot_description/meshes/3fg15/visual/right_finger.stl" scale="0.001 0.001 0.001"/>
        </geometry>
      </visual>
      <collision>
        <origin xyz="0 0 0" rpy="0 0 0"/>
        <geometry>
          <mesh filename="package://onrobot_description/meshes/3fg15/collision/right_finger.stl" scale="0.001 0.001 0.001"/>
        </geometry>
      </collision>
    </link>

    <!-- Middle Finger -->
    <link name="${prefix}middle_finger_link">
      <inertial>
        <origin xyz="0 0 0" rpy="0 0 0"/>
        <mass value="0.08"/>
        <inertia ixx="0.00008" ixy="0.0" ixz="0.0" iyy="0.00008" iyz="0.0" izz="0.00008"/>
      </inertial>
      <visual>
        <origin xyz="0 0 0" rpy="0 0 0"/>
        <geometry>
          <mesh filename="package://onrobot_description/meshes/3fg15/visual/middle_finger.stl" scale="0.001 0.001 0.001"/>
        </geometry>
      </visual>
      <collision>
        <origin xyz="0 0 0" rpy="0 0 0"/>
        <geometry>
          <mesh filename="package://onrobot_description/meshes/3fg15/collision/middle_finger.stl" scale="0.001 0.001 0.001"/>
        </geometry>
      </collision>
    </link>

    <!-- Dummy link para control -->
    <link name="${prefix}finger_width_mock_link"/>

    <!-- JOINT PRINCIPAL (para el driver) -->
    <joint name="${prefix}finger_diameter" type="prismatic">
      <parent link="${prefix}onrobot_base_link"/>
      <child link="${prefix}finger_width_mock_link"/>
      <origin xyz="0 0 0" rpy="0 0 0"/>
      <axis xyz="0 1 0"/>
      <limit lower="0.0" upper="0.150" effort="200" velocity="0.5"/>
    </joint>

    <!-- === DEDOS: REVOLUTE + MIMIC === -->
    <xacro:property name="angle_per_meter" value="${(2*pi/3)/(0.150 - 0.0)}" />  <!-- 120° en 150mm -->
    <xacro:property name="min_angle" value="${-pi/3}" />  <!-- -60° -->
    <xacro:property name="offset" value="${min_angle - angle_per_meter * 0.0}" />

    <!-- Left Finger -->
    <joint name="${prefix}left_finger_joint" type="revolute">
      <parent link="${prefix}onrobot_base_link"/>
      <child link="${prefix}left_finger_link"/>
      <origin xyz="0 0 0" rpy="${pi}" />
      <axis xyz="0 0 1"/>
      <limit lower="${-pi/3}" upper="${pi/3}" effort="200" velocity="0.5"/>
      <mimic joint="${prefix}finger_diameter" multiplier="${angle_per_meter}" offset="${offset}"/>
    </joint>

    <!-- Right Finger -->
    <joint name="${prefix}right_finger_joint" type="revolute">
      <parent link="${prefix}onrobot_base_link"/>
      <child link="${prefix}right_finger_link"/>
      <origin xyz="0 0 0" rpy="0" />
      <axis xyz="0 0 1"/>
      <limit lower="${-pi/3}" upper="${pi/3}" effort="200" velocity="0.5"/>
      <mimic joint="${prefix}finger_diameter" multiplier="${angle_per_meter}" offset="${offset}"/>
    </joint>

    <!-- Middle Finger -->
    <joint name="${prefix}middle_finger_joint" type="revolute">
      <parent link="${prefix}onrobot_base_link"/>
      <child link="${prefix}middle_finger_link"/>
      <origin xyz="0 0 0" rpy="${2*pi/3}" />
      <axis xyz="0 0 1"/>
      <limit lower="${-pi/3}" upper="${pi/3}" effort="200" velocity="0.5"/>
      <mimic joint="${prefix}finger_diameter" multiplier="${angle_per_meter}" offset="${offset}"/>
    </joint>

    <!-- TCP -->
    <link name="${prefix}gripper_tcp"/>
    <joint name="${prefix}tcp_joint" type="fixed">
      <parent link="${prefix}onrobot_base_link"/>
      <child link="${prefix}gripper_tcp"/>
      <origin xyz="0 0 0.13" rpy="0 0 0"/>
    </joint>

    <!-- Transmission -->
    <xacro:transmission_macro prefix="${prefix}" joint_name="finger_diameter"/>

  </xacro:macro>
</robot>