<?xml version="1.0"?>
<robot xmlns:xacro="http://ros.org/wiki/xacro">
  <xacro:include filename="$(find onrobot_description)/urdf/inc/common_utils.xacro" />
  <xacro:include filename="$(find onrobot_description)/urdf/inc/2fg7_materials.xacro" />

  <!-- ============================================= -->
  <!-- MACRO: OnRobot 3FG15 (estructura IGUAL a 2FG7) -->
  <!-- STL COMPLETO → solo base_link con visual     -->
  <!-- ============================================= -->
  <xacro:macro name="onrobot_3fg15" params="prefix onrobot_type:='3fg15'">

    <!-- ====================== Base Link (STL COMPLETO del 3FG15) ====================== -->
    <link name="${prefix}onrobot_base_link">
      <inertial>
        <origin xyz="0 0 0.05" rpy="${-pi/2} 0 0"/>
        <mass value="1.2"/>
        <inertia ixx="0.012" ixy="0.0" ixz="0.0" iyy="0.012" iyz="0.0" izz="0.008"/>
      </inertial>
      <visual>
        <origin xyz="0 0 0.05" rpy="${-pi/2} 0 0"/>
        <geometry>
          <mesh filename="package://onrobot_description/meshes/3fg15/visual/3fg15.stl" scale="0.001 0.001 0.001"/>
        </geometry>
        <material name="onrobot_silver"/>
      </visual>
      <collision>
        <origin xyz="0 0 0.05" rpy="${-pi/2} 0 0"/>
        <geometry>
          <mesh filename="package://onrobot_description/meshes/3fg15/collision/3fg15.stl" scale="0.001 0.001 0.001"/>
        </geometry>
      </collision>
    </link>

    <!-- ====================== Dummy Links para simular movimiento (solo para joint) ====================== -->
    <!-- No tienen STL → solo para el joint principal (finger_width) -->
    <link name="${prefix}left_finger_link">
      <inertial>
        <origin xyz="0 0 0" rpy="0 0 0"/>
        <mass value="0.01"/>
        <inertia ixx="0.00001" ixy="0.0" ixz="0.0" iyy="0.00001" iyz="0.0" izz="0.00001"/>
      </inertial>
      <visual>
        <origin xyz="0 0 0" rpy="0 0 0"/>
        <geometry>
          <box size="0.001 0.001 0.001"/> <!-- invisible -->
        </geometry>
      </visual>
      <collision>
        <origin xyz="0 0 0" rpy="0 0 0"/>
        <geometry>
          <box size="0.001 0.001 0.001"/>
        </geometry>
      </collision>
    </link>

    <link name="${prefix}right_finger_link">
      <inertial>
        <origin xyz="0 0 0" rpy="0 0 0"/>
        <mass value="0.01"/>
        <inertia ixx="0.00001" ixy="0.0" ixz="0.0" iyy="0.00001" iyz="0.0" izz="0.00001"/>
      </inertial>
      <visual>
        <origin xyz="0 0 0" rpy="0 0 0"/>
        <geometry>
          <box size="0.001 0.001 0.001"/> <!-- invisible -->
        </geometry>
      </visual>
      <collision>
        <origin xyz="0 0 0" rpy="0 0 0"/>
        <geometry>
          <box size="0.001 0.001 0.001"/>
        </geometry>
      </collision>
    </link>

    <!-- ====================== Dummy link for the main control joint ====================== -->
    <link name="${prefix}finger_width_mock_link"/>

    <!-- ====================== Main control joint (finger_width) ====================== -->
    <joint name="${prefix}finger_width" type="prismatic">
      <origin xyz="0 0 0" rpy="0 0 0"/>
      <parent link="${prefix}onrobot_base_link"/>
      <child link="${prefix}finger_width_mock_link"/>
      <axis xyz="0 0 1"/>
      <limit lower="0.0" upper="0.15" velocity="0.25" effort="200"/>
    </joint>

    <!-- ====================== Left Finger Joint (mimic) ====================== -->
    <joint name="${prefix}left_finger_joint" type="prismatic">
      <origin xyz="-0.075 0 0" rpy="0 0 0"/>
      <parent link="${prefix}onrobot_base_link"/>
      <child link="${prefix}left_finger_link"/>
      <axis xyz="1 0 0"/>
      <limit lower="0.0" upper="0.075" effort="200" velocity="0.25"/>
      <mimic joint="${prefix}finger_width" multiplier="0.5" offset="0"/>
    </joint>

    <!-- ====================== Right Finger Joint (mimic) ====================== -->
    <joint name="${prefix}right_finger_joint" type="prismatic">
      <origin xyz="0.075 0 0" rpy="0 0 0"/>
      <parent link="${prefix}onrobot_base_link"/>
      <child link="${prefix}right_finger_link"/>
      <axis xyz="-1 0 0"/>
      <limit lower="-0.075" upper="0." effort="200" velocity="0.25"/>
      <mimic joint="${prefix}finger_width" multiplier="0.5" offset="0"/>
    </joint>

    <!-- ====================== TCP Link ====================== -->
    <link name="${prefix}gripper_tcp"/>
    <joint name="${prefix}tcp_joint" type="fixed">
      <origin xyz="0 0 0.08" rpy="0 0 0"/>
      <parent link="${prefix}onrobot_base_link"/>
      <child link="${prefix}gripper_tcp"/>
    </joint>

    <!-- ====================== Transmission for ROS Control (IGUAL QUE 2FG7) ====================== -->
    <xacro:transmission_macro prefix="${prefix}" joint_name="finger_width"/>

  </xacro:macro>
</robot>